def fail(event, context):
    raise Exception('Exception occured')
